Workbook

Sheet Dashboard
A1: NDIJOB GLOBAL — FINANCIAL DASHBOARD
A2: Report Date: June 27, 2026
B4: OPENING ACCOUNT BALANCE | F4: TOTAL PLEDGES (Job Family)
B5: 2950000 | F5: =Pledges!C17
B7: TOTAL EVENT EXPENSES | F7: BALANCE AFTER EVENT
B8: ='Event Expenses'!D17 | F8: ='Event Expenses'!D18
B10: TOTAL GIFTS RECEIVED | F10: GROSS TOTAL (before post-exp)
B11: ='Gifts from Invitees'!C21 | F11: ='Gifts from Invitees'!C22
B13: TOTAL POST-EVENT EXPENSES | F13: NET FINAL BALANCE
B14: ='Post-Event Expenses'!C7 | F14: ='Balance Summary'!D50
B16: EVENT EXPENSE BREAKDOWN
B17: DJ | C17: 120000 | D17: =IFERROR(C17/'Event Expenses'!D17,0)
B18: Advert | C18: 120000 | D18: =IFERROR(C18/'Event Expenses'!D17,0)
B19: Caterer | C19: 430000 | D19: =IFERROR(C19/'Event Expenses'!D17,0)
B20: Canopies, Tables & Chairs | C20: 150000 | D20: =IFERROR(C20/'Event Expenses'!D17,0)
B21: Registration of Name | C21: 42000 | D21: =IFERROR(C21/'Event Expenses'!D17,0)
B22: Decorations | C22: 110000 | D22: =IFERROR(C22/'Event Expenses'!D17,0)
B23: Drinks / Water | C23: 348400 | D23: =IFERROR(C23/'Event Expenses'!D17,0)
B24: XXXXLT-Shirts | C24: 48000 | D24: =IFERROR(C24/'Event Expenses'!D17,0)
B25: Meat / Garden Egg / Kolanut | C25: 525000 | D25: =IFERROR(C25/'Event Expenses'!D17,0)
B26: Firewood | C26: 30000 | D26: =IFERROR(C26/'Event Expenses'!D17,0)
B27: MC | C27: 130000 | D27: =IFERROR(C27/'Event Expenses'!D17,0)
B28: Ice Block | C28: 12000 | D28: =IFERROR(C28/'Event Expenses'!D17,0)
B29: Shehu (Cash) | C29: 8000 | D29: =IFERROR(C29/'Event Expenses'!D17,0)
B31: GIFTS FROM INVITEES
B32: Nkechi Umunakwe | C32: 150000 | D32: =IFERROR(C32/'Gifts from Invitees'!C21,0)
B33: Casmir Chimankpam Ebelleme | C33: 20000 | D33: =IFERROR(C33/'Gifts from Invitees'!C21,0)
B34: Max | C34: 100000 | D34: =IFERROR(C34/'Gifts from Invitees'!C21,0)
B35: Prof BEB Nwoke | C35: 100000 | D35: =IFERROR(C35/'Gifts from Invitees'!C21,0)
B36: Benedict | C36: 1000000 | D36: =IFERROR(C36/'Gifts from Invitees'!C21,0)
B37: Chibuzor | C37: 50000 | D37: =IFERROR(C37/'Gifts from Invitees'!C21,0)
B38: Odoh Chike Nnaemeka | C38: 100000 | D38: =IFERROR(C38/'Gifts from Invitees'!C21,0)
B39: Odoh Chike Nnaemeka | C39: 21000 | D39: =IFERROR(C39/'Gifts from Invitees'!C21,0)
B40: Cash – Day of Event | C40: 153000 | D40: =IFERROR(C40/'Gifts from Invitees'!C21,0)
B41: Emma Obinikpa | C41: 100000 | D41: =IFERROR(C41/'Gifts from Invitees'!C21,0)
B42: Odoh Chike Nnamdi | C42: 500000 | D42: =IFERROR(C42/'Gifts from Invitees'!C21,0)
B43: Mrs Pearl Kanu | C43: 200000 | D43: =IFERROR(C43/'Gifts from Invitees'!C21,0)
B44: Mrs Ibekwe | C44: 500000 | D44: =IFERROR(C44/'Gifts from Invitees'!C21,0)
B45: Favour Njoku | C45: 100000 | D45: =IFERROR(C45/'Gifts from Invitees'!C21,0)
B46: Ify Ohameje | C46: 200000 | D46: =IFERROR(C46/'Gifts from Invitees'!C21,0)
...

Sheet Cover
A1: NDIJOB GLOBAL
A2: FINANCIAL WORKBOOK — EVENT & OPERATIONS FUND
A3: Generated: June 27, 2026 | All figures in Nigerian Naira (₦)
A5: CONTENTS | C5: Description
A6: Pledges | C6: Job Family contributions & payments
A7: Event Expenses | C7: All expenses incurred for the event
A8: Gifts | C8: Donations received from event invitees
A9: Post-Event Exp. | C9: Infrastructure & operational spending
A10: Balance Summary | C10: Full running statement with net balance
A11: Dashboard | C11: Visual summary of all key figures

Sheet Pledges
A1: NDIJOB GLOBAL — PLEDGES & CONTRIBUTIONS
A2: All amounts in Nigerian Naira (₦) | Generated: June 27, 2026
A3: # | B3: Name | C3: Amount Pledged (₦) | D3: Amount Paid (₦) | E3: Outstanding (₦) | F3: % Paid | G3: Status
A4: 1 | B4: Job Sweet | C4: 1150000 | D4: 1150000 | E4: =C4-D4 | F4: =IFERROR(D4/C4,0) | G4: Paid
A5: 2 | B5: Job Paddy | C5: 1000000 | D5: 1000000 | E5: =C5-D5 | F5: =IFERROR(D5/C5,0) | G5: Paid
A6: 3 | B6: Job PJ | C6: 300000 | D6: 300000 | E6: =C6-D6 | F6: =IFERROR(D6/C6,0) | G6: Paid
A7: 4 | B7: Job Kalota | C7: 200000 | D7: 200000 | E7: =C7-D7 | F7: =IFERROR(D7/C7,0) | G7: Paid
A8: 5 | B8: Job Shehu | C8: 50000 | D8: 50000 | E8: =C8-D8 | F8: =IFERROR(D8/C8,0) | G8: Paid
A9: 6 | B9: Job Nelcon | C9: 10000 | D9: 10000 | E9: =C9-D9 | F9: =IFERROR(D9/C9,0) | G9: Paid
A10: 7 | B10: Job Chi | C10: 100000 | D10: 100000 | E10: =C10-D10 | F10: =IFERROR(D10/C10,0) | G10: Paid
A11: 8 | B11: Job Nkiru | C11: 10000 | D11: 10000 | E11: =C11-D11 | F11: =IFERROR(D11/C11,0) | G11: Paid
A12: 9 | B12: Job Ngozi | C12: 50000 | D12: 50000 | E12: =C12-D12 | F12: =IFERROR(D12/C12,0) | G12: Paid
A13: 10 | B13: Job Father | C13: 200000 | D13: 200000 | E13: =C13-D13 | F13: =IFERROR(D13/C13,0) | G13: Paid
A14: 11 | B14: Job Nora | C14: 50000 | D14: 50000 | E14: =C14-D14 | F14: =IFERROR(D14/C14,0) | G14: Paid
A15: 12 | B15: Job Ndy | C15: 100000 | D15: 100000 | E15: =C15-D15 | F15: =IFERROR(D15/C15,0) | G15: Paid
A16: 13 | B16: Job Onyi | C16: 30000 | D16: 30000 | E16: =C16-D16 | F16: =IFERROR(D16/C16,0) | G16: Paid
A17: TOTAL PLEDGES / PAYMENTS | C17: =SUM(C4:C16) | D17: =SUM(D4:D16) | E17: =SUM(E4:E16)
A18: ★ Money deposited in account: ₦2,950,000

Sheet Event Expenses
A1: NDIJOB GLOBAL — EVENT EXPENSES
A2: All amounts in Nigerian Naira (₦) | Generated: June 27, 2026
A3: # | B3: Description | C3: Category | D3: Amount (₦) | E3: Status | F3: Notes
A4: 1 | B4: DJ | C4: Entertainment | D4: 120000 | E4: Paid
A5: 2 | B5: Advert | C5: Marketing | D5: 120000 | E5: Full Payment
A6: 3 | B6: Caterer | C6: Catering | D6: 430000 | E6: Paid
A7: 4 | B7: Canopies, Tables & Chairs | C7: Venue | D7: 150000 | E7: Full Payment
A8: 5 | B8: Registration of Name | C8: Administrative | D8: 42000 | E8: Pending
A9: 6 | B9: Decorations | C9: Venue | D9: 110000 | E9: Pending
A10: 7 | B10: Drinks / Water | C10: Catering | D10: 348400 | E10: Full Payment
A11: 8 | B11: XXXXLT-Shirts | C11: Merchandise | D11: 48000 | E11: Full Payment
A12: 9 | B12: Meat / Garden Egg / Kolanut | C12: Catering | D12: 525000 | E12: Pending
A13: 10 | B13: Firewood | C13: Catering | D13: 30000 | E13: Pending
A14: 11 | B14: MC | C14: Entertainment | D14: 130000 | E14: Paid
A15: 12 | B15: Ice Block | C15: Catering | D15: 12000 | E15: Paid
A16: 13 | B16: Shehu (Cash) | C16: Administrative | D16: 8000 | E16: Paid
A17: TOTAL EVENT EXPENSES | D17: =SUM(D4:D16)
A18: BALANCE AFTER EVENT EXPENSES | D18: =2950000-D17
A19: ★ Stated balance per records: ₦986,600

Sheet Gifts from Invitees
A1: NDIJOB GLOBAL — GIFTS FROM INVITEES
A2: All amounts in Nigerian Naira (₦) | Generated: June 27, 2026
A3: Balance B/F (after event expenses) | D3: 986600
A4: # | B4: Name / Source | C4: Amount (₦) | D4: Status | E4: Notes
A5: 1 | B5: Nkechi Umunakwe | C5: 150000 | D5: Received | E5: Received
A6: 2 | B6: Casmir Chimankpam Ebelleme | C6: 20000 | D6: Received | E6: Received
A7: 3 | B7: Max | C7: 100000 | D7: Received | E7: Received
A8: 4 | B8: Prof BEB Nwoke | C8: 100000 | D8: Received | E8: Received
A9: 5 | B9: Benedict | C9: 1000000 | D9: Received | E9: Received
A10: 6 | B10: Chibuzor | C10: 50000 | D10: Received | E10: Cash Collected
A11: 7 | B11: Odoh Chike Nnaemeka | C11: 100000 | D11: Received | E11: Refund – Meat Purchase
A12: 8 | B12: Odoh Chike Nnaemeka | C12: 21000 | D12: Received | E12: Refund – 3 T-Shirts Not Bought
A13: 9 | B13: Cash – Day of Event | C13: 153000 | D13: Received | E13: Received
A14: 10 | B14: Emma Obinikpa | C14: 100000 | D14: Paid
A15: 11 | B15: Odoh Chike Nnamdi | C15: 500000 | D15: Paid
A16: 12 | B16: Mrs Pearl Kanu | C16: 200000 | D16: Paid
A17: 13 | B17: Mrs Ibekwe | C17: 500000 | D17: Paid
A18: 14 | B18: Favour Njoku | C18: 100000 | D18: Paid
A19: 15 | B19: Ify Ohameje | C19: 200000 | D19: Paid
A20: 16 | B20: Dubem Nnayere Odoh | C20: 400000 | D20: Paid | E20: Bal ₦300k Outstanding
A21: TOTAL GIFTS RECEIVED | C21: =SUM(C5:C20)
A22: GRAND TOTAL (B/F + Gifts) | C22: =986600+C21

Sheet Post-Event Expenses
A1: NDIJOB GLOBAL — POST-EVENT EXPENSES
A2: Infrastructure & operational expenditure | Generated: June 27, 2026
A3: # | B3: Description | C3: Amount (₦) | D3: Status | E3: Notes
A4: 1 | B4: Full Payment – Tank Stand | C4: 1921600
A5: 2 | B5: Cutting of Grass | C5: 20000
A6: 3 | B6: First Instalment – Borehole | C6: 2759500
A7: TOTAL POST-EVENT EXPENSES | C7: =SUM(C4:C6)

Sheet Balance Summary
A1: NDIJOB GLOBAL — RUNNING FINANCIAL STATEMENT
A2: As at June 27, 2026
A3: Item | C3: Amount (₦) | D3: Running Balance (₦)
A4: A. OPENING — JOB FAMILY CONTRIBUTIONS
A5: Money deposited in account | C5: 2950000 | D5: 2950000
A7: B. EVENT EXPENSES
A8: 1. DJ | C8: 120000
A9: 2. Advert | C9: 120000
A10: 3. Caterer | C10: 430000
A11: 4. Canopies, Tables & Chairs | C11: 150000
A12: 5. Registration of Name | C12: 42000
A13: 6. Decorations | C13: 110000
A14: 7. Drinks / Water | C14: 348400
A15: 8. XXXXLT-Shirts | C15: 48000
A16: 9. Meat / Garden Egg / Kolanut | C16: 525000
A17: 10. Firewood | C17: 30000
A18: 11. MC | C18: 130000
A19: 12. Ice Block | C19: 12000
A20: 13. Shehu (Cash) | C20: 8000
A21: TOTAL EVENT EXPENSES | C21: =SUM(C8:C20) | D21: =2950000-C21
A22: ★ Stated balance after event expenses: ₦986,600
A24: C. GIFTS FROM INVITEES
A25: 1. Nkechi Umunakwe | C25: 150000
A26: 2. Casmir Chimankpam Ebelleme | C26: 20000
A27: 3. Max | C27: 100000
A28: 4. Prof BEB Nwoke | C28: 100000
A29: 5. Benedict | C29: 1000000
A30: 6. Chibuzor | C30: 50000
A31: 7. Odoh Chike Nnaemeka | C31: 100000
A32: 8. Odoh Chike Nnaemeka | C32: 21000
A33: 9. Cash – Day of Event | C33: 153000
A34: 10. Emma Obinikpa | C34: 100000
A35: 11. Odoh Chike Nnamdi | C35: 500000
A36: 12. Mrs Pearl Kanu | C36: 200000
... A40: 16. Dubem Nnayere Odoh | C40: 400000
A41: TOTAL GIFTS RECEIVED | C41: =SUM(C25:C40) | D41: =986600+C41
A42: GROSS TOTAL AVAILABLE (29/12/2025) | D42: =D41
A44: D. POST-EVENT EXPENSES
A45: 1. Full Payment – Tank Stand | C45: 1921600
A46: 2. Cutting of Grass | C46: 20000
...
